Workbook
Name AñoCalendario: #REF!
Name asd: #REF!
Name DIAS: 'ASISTENCIA '!$C$64:$D$69
Name Excel_BuiltIn__FilterDatabase_6: #REF!
Name Feriados: 'ASISTENCIA '!#REF!
Name InicioDeSemana: #REF!
Name TítuloDeColumnaRegión1..I12.1: #REF!
Name TítuloDeColumnaRegión1..I12.2: #REF!
Name TítuloDeColumnaRegión2..D14.1: #REF!
Name TítuloDeColumnaRegión2..D14.2: #REF!
Name TítuloDeFilaRegión1..F13.2: #REF!
Name TítuloDeFilaRegión1..L3.1: #REF!

Sheet ASISTENCIA 
C1: SERVICIO NACIONAL DE APRENDIZAJE CENTRO DE GESTION DE MERCADOS, LOGISTICA Y TEGNOLOGIAS DE LA INFORMACIÓN SEGUIMIENTO DE INASISTENCIAS | G1: ACTIVIDADES DE PROYECTO | CS1: CIERRE DE AÑO ESCOLAR | CY1: TOTAL APRENDICES MATRICULADOS:
G2: GUÍAS | CY2: =COUNTA('BASE DE DATOS'!B26:B50) -> 25
A3: PROGRAMA DE FORMACIÓN: | D3: COMUNICACIÓN Y MARKETING | G3: COMPETENCIAS
A4: INSTRUCTOR SENA: | D4: CARLOS ALBERTO SALCEDO DURAN | G4: RESULTADOS DE APRENDIZAJE | CY4: CE | DA4: CON EXCUSA | DJ4: SE | DL4: SIN EXCUSA
A5: INSTITUCIÓN EDUCATIVA: | D5: ='BASE DE DATOS'!C7 -> COLEGIO JUAN LUIS LONDOÑO I.E.D. LA SALLE
A6: FICHA O GRUPO: | D6: ='BASE DE DATOS'!C4 -> 3415417 | E6: GRADO: | F6: ='BASE DE DATOS'!G7 -> 10 | G6: =CY1 & " " & CY2 -> TOTAL APRENDICES MATRICULADOS: 25 | P6: =TEXT(P7,"MMM") -> mar | Q6: =TEXT(Q7,"MMM") -> mar | R6: =TEXT(R7,"MMM") -> mar | S6: =TEXT(S7,"MMM") -> mar | T6: =TEXT(T7,"MMM") -> mar | U6: =TEXT(U7,"MMM") -> mar | V6: =TEXT(V7,"MMM") -> mar | W6: =TEXT(W7,"MMM") -> mar | ... CW6: =TEXT(CW7,"MMM") -> dic | CX6: HORAS TOTALES DE INASISTENCIAS MENSUAL DEL APRENDIZ
A7: PRIMER DÍA DE FORMACIÓN: | D7: ='BASE DE DATOS'!G5 -> 46083 | E7: SEGUNDO DÍA DE FORMACIÓN: | F7: ='BASE DE DATOS'!G6 -> 46085 | P7: =D7 -> 46083 | Q7: =F7 -> 46085 | R7: =IF('BASE DE DATOS'!$G$4=1,(Q7+7),IF('BASE DE DATOS'!$G$4=2,(P7+7))) -> 46090 | S7: =IF('BASE DE DATOS'!$G$4=1,(R7+7),IF('BASE DE DATOS'!$G$4=2,(Q7+7))) -> 46092 | T7: =IF('BASE DE DATOS'!$G$4=1,(S7+7),IF('BASE DE DATOS'!$G$4=2,(R7+7))) -> 46097 | U7: =IF('BASE DE DATOS'!$G$4=1,(T7+7),IF('BASE DE DATOS'!$G$4=2,(S7+7))) -> 46099 | V7: =IF('BASE DE DATOS'!$G$4=1,(U7+7),IF('BASE DE DATOS'!$G$4=2,(T7+7))) -> 46104 | W7: =IF('BASE DE DATOS'!$G$4=1,(V7+7),IF('BASE DE DATOS'!$G$4=2,(U7+7))) -> 46106 | X7: =IF('BASE DE DATOS'!$G$4=1,(W7+7),IF('BASE DE DATOS'!$G$4=2,(V7+7))) -> 46111 | Y7: =IF('BASE DE DATOS'!$G$4=1,(X7+7),IF('BASE DE DATOS'!$G$4=2,(W7+7))) -> 46113 | ... CW7: =IF('BASE DE DATOS'!$G$4=1,(CV7+7),IF('BASE DE DATOS'!$G$4=2,(CU7+7))) -> 46379 | CX7: ene | CZ7: feb | DB7: mar | DD7: abr | DF7: may | DH7: jun | DJ7: jul | DL7: ago | DN7: sep | DP7: oct | DR7: nov | DT7: dic | DV7: TOTAL
A8: No | B8: TIP_DOC | C8: IDENTIFICACIÓN | D8: NOMBRES Y APELLIDOS | E8: ESTADO | F8: ALETA DE INASISTENCIAS Y OBSEVACIONES | G8: A | H8: CE | I8: SE | J8: INC | K8: LIC | L8: CLM | M8: SFF | N8: RET | O8: % INASISTENCIAS | P8: =D7 -> 46083 | Q8: =F7 -> 46085 | R8: =P8+7 -> 46090 | S8: =Q8+7 -> 46092 | T8: =R8+7 -> 46097 | U8: =S8+7 -> 46099 | V8: =T8+7 -> 46104 | W8: =U8+7 -> 46106 | X8: =V8+7 -> 46111 | Y8: =W8+7 -> 46113 | ... CW8: =CU8+7 -> 46379 | CX8: CE | CY8: SE | CZ8: CE | DA8: SE | DB8: CE | DC8: SE | DD8: CE | DE8: SE | DF8: CE | DG8: SE | DH8: CE | DI8: SE | DJ8: CE | DK8: SE | DL8: CE | DM8: SE | DN8: CE | DO8: SE | DP8: CE | DQ8: SE | DR8: CE | DS8: SE | DT8: CE | DU8: SE | DV8: CE | DW8: SE | DY8: PROGRMAS
A9: 1 | B9: ='BASE DE DATOS'!C10 -> TI | C9: ='BASE DE DATOS'!D10 -> 1011210598 | D9: ='BASE DE DATOS'!B10 -> Caren Sofía Acevedo Cortés | E9: EN FORMACIÓN | F9: =IF(I9=0,"",IF(I9>=5,"FALTAS INTERMITENTES",IF(I9>=3,"REVISAR FALTAS",IF(AND(I9<3,I9>0),"CON FALTAS")))) | G9: =COUNTIF(P9:CR9,"A") -> 20 | H9: =COUNTIF(P9:CR9,"CE") -> 0 | I9: =COUNTIF(P9:CR9,"SE") -> 0 | J9: =COUNTIF(P9:CR9,"INC") -> 0 | K9: =COUNTIF(P9:CR9,"LIC") -> 0 | L9: =COUNTIF(P9:CR9,"CLM") -> 0 | M9: =COUNTIF(P9:IA9,"SFF") -> 0 | N9: =COUNTIF(P9:CR9,"RET") -> 0 | O9: =IFERROR(SUM(H9:K9)/SUM(G9:K9)," ") -> 0 | P9: A | Q9: A | R9: A | S9: A | T9: A | U9: A | V9: A | W9: A | X9: A | Y9: A | Z9: A | AA9: A | AB9: A | AC9: A | AD9: A | AE9: A | AF9: A | AG9: A | AH9: A | AI9: A | DV9: =CX9+CZ9+DB9+DD9+DF9+DH9+DJ9+DL9+DN9+DP9+DR9+DT9 -> 0 | DW9: =CY9+DA9+DC9+DE9+DG9+DI9+DK9+DM9+DO9+DQ9+DS9+DU9 -> 0 | DY9: 1 VENTA DE PRODUCTOS EN LINEA. 632201. v1
A10: =A9+1 -> 2 | B10: ='BASE DE DATOS'!C11 -> TI | C10: ='BASE DE DATOS'!D11 -> 1021683093 | D10: ='BASE DE DATOS'!B11 -> Helen Natalia Aperador Abaunza | E10: EN FORMACIÓN | F10: =IF(I10=0,"",IF(I10>=5,"FALTAS INTERMITENTES",IF(I10>=3,"REVISAR FALTAS",IF(AND(I10<3,I10>0),"CON FALTAS")))) | G10: =COUNTIF(P10:CR10,"A") -> 20 | H10: =COUNTIF(P10:CR10,"CE") -> 0 | I10: =COUNTIF(P10:CR10,"SE") -> 0 | J10: =COUNTIF(P10:CR10,"INC") -> 0 | K10: =COUNTIF(P10:CR10,"LIC") -> 0 | L10: =COUNTIF(P10:CR10,"CLM") -> 0 | M10: =COUNTIF(P10:IA10,"SFF") -> 0 | N10: =COUNTIF(P10:CR10,"RET") -> 0 | O10: =IFERROR(SUM(H10:K10)/SUM(G10:K10)," ") -> 0 | P10: A | Q10: A | R10: A | S10: A | T10: A | U10: A | V10: A | W10: A | X10: A | Y10: A | Z10: A | AA10: A | AB10: A | AC10: A | AD10: A | AE10: A | AF10: A | AG10: A | AH10: A | AI10: A | DV10: =CX10+CZ10+DB10+DD10+DF10+DH10+DJ10+DL10+DN10+DP10+DR10+DT10 -> 0 | DW10: =CY10+DA10+DC10+DE10+DG10+DI10+DK10+DM10+DO10+DQ10+DS10+DU10 -> 0 | DY10: 2 ASESORIA COMERCIAL. 631101. V2
A11: =A10+1 -> 3 | B11: ='BASE DE DATOS'!C12 -> TI | C11: ='BASE DE DATOS'!D12 -> 1028867289 | D11: ='BASE DE DATOS'!B12 -> Paula Valentina Ardila Franco | E11: EN FORMACIÓN | F11: =IF(I11=0,"",IF(I11>=5,"FALTAS INTERMITENTES",IF(I11>=3,"REVISAR FALTAS",IF(AND(I11<3,I11>0),"CON FALTAS")))) | G11: =COUNTIF(P11:CR11,"A") -> 20 | H11: =COUNTIF(P11:CR11,"CE") -> 0 | I11: =COUNTIF(P11:CR11,"SE") -> 0 | J11: =COUNTIF(P11:CR11,"INC") -> 0 | K11: =COUNTIF(P11:CR11,"LIC") -> 0 | L11: =COUNTIF(P11:CR11,"CLM") -> 0 | M11: =COUNTIF(P11:IA11,"SFF") -> 0 | N11: =COUNTIF(P11:CR11,"RET") -> 0 | O11: =IFERROR(SUM(H11:K11)/SUM(G11:K11)," ") -> 0 | P11: A | Q11: A | R11: A | S11: A | T11: A | U11: A | V11: A | W11: A | X11: A | Y11: A | Z11: A | AA11: A | AB11: A | AC11: A | AD11: A | AE11: A | AF11: A | AG11: A | AH11: A | AI11: A | DV11: =CX11+CZ11+DB11+DD11+DF11+DH11+DJ11+DL11+DN11+DP11+DR11+DT11 -> 0 | DW11: =CY11+DA11+DC11+DE11+DG11+DI11+DK11+DM11+DO11+DQ11+DS11+DU11 -> 0 | DY11: 3 INTEGRACION DE OPERACIONES LOGISTICAS. 137136. v1
A12: =A11+1 -> 4 | B12: ='BASE DE DATOS'!C13 -> TI | C12: ='BASE DE DATOS'!D13 -> 1016718433 | D12: ='BASE DE DATOS'!B13 -> Janny Sofia Ariza Marín | E12: EN FORMACIÓN | F12: =IF(I12=0,"",IF(I12>=5,"FALTAS INTERMITENTES",IF(I12>=3,"REVISAR FALTAS",IF(AND(I12<3,I12>0),"CON FALTAS")))) -> REVISAR FALTAS | G12: =COUNTIF(P12:CR12,"A") -> 12 | H12: =COUNTIF(P12:CR12,"CE") -> 0 | I12: =COUNTIF(P12:CR12,"SE") -> 4 | J12: =COUNTIF(P12:CR12,"INC") -> 0 | K12: =COUNTIF(P12:CR12,"LIC") -> 0 | L12: =COUNTIF(P12:CR12,"CLM") -> 0 | M12: =COUNTIF(P12:IA12,"SFF") -> 0 | N12: =COUNTIF(P12:CR12,"RET") -> 65 | O12: =IFERROR(SUM(H12:K12)/SUM(G12:K12)," ") -> 0.25 | P12: A | Q12: A | R12: A | S12: A | T12: A | U12: A | V12: A | W12: A | X12: A | Y12: A | Z12: SE | AA12: SE | AB12: SE | AC12: SE | AD12: RET | AE12: RET | AF12: A | AG12: A | AH12: RET | AI12: RET | AJ12: RET | AK12: RET | AL12: RET | AM12: RET | AN12: RET | AO12: RET | AP12: RET | AQ12: RET | AR12: RET | AS12: RET | AT12: RET | AU12: RET | AV12: RET | AW12: RET | AX12: RET | AY12: RET | AZ12: RET | BA12: RET | BB12: RET | BC12: RET | BD12: RET | BE12: RET | BF12: RET | BG12: RET | BH12: RET | BI12: RET | BJ12: RET | BK12: RET | BL12: RET | BM12: RET | BN12: RET | BO12: RET | BP12: RET | BQ12: RET | BR12: RET | BS12: RET | BT12: RET | BU12: RET | BV12: RET | BW12: RET | BX12: RET | BY12: RET | BZ12: RET | CA12: RET | CB12: RET | CC12: RET | CD12: RET | CE12: RET | CF12: RET | CG12: RET | CH12: RET | CI12: RET | CJ12: RET | CK12: RET | CL12: RET | CM12: RET | CN12: RET | CO12: RET | CP12: RET | CQ12: RET | CR12: RET | CS12: RET | CT12: RET | CU12: RET | CV12: RET | CW12: RET | DV12: =CX12+CZ12+DB12+DD12+DF12+DH12+DJ12+DL12+DN12+DP12+DR12+DT12 -> 0 | DW12: =CY12+DA12+DC12+DE12+DG12+DI12+DK12+DM12+DO12+DQ12+DS12+DU12 -> 0 | DY12: 4 OPERACIONES DE COMERCIO EXTERIOR. 134600. v1
A13: =A12+1 -> 5 | B13: ='BASE DE DATOS'!C14 -> TI | C13: ='BASE DE DATOS'!D14 -> 1013128025 | D13: ='BASE DE DATOS'!B14 -> Damián Felipe Benavides Pérez | E13: EN FORMACIÓN | F13: =IF(I13=0,"",IF(I13>=5,"FALTAS INTERMITENTES",IF(I13>=3,"REVISAR FALTAS",IF(AND(I13<3,I13>0),"CON FALTAS")))) -> CON FALTAS | G13: =COUNTIF(P13:CR13,"A") -> 18 | H13: =COUNTIF(P13:CR13,"CE") -> 0 | I13: =COUNTIF(P13:CR13,"SE") -> 2 | J13: =COUNTIF(P13:CR13,"INC") -> 0 | K13: =COUNTIF(P13:CR13,"LIC") -> 0 | L13: =COUNTIF(P13:CR13,"CLM") -> 0 | M13: =COUNTIF(P13:IA13,"SFF") -> 0 | N13: =COUNTIF(P13:CR13,"RET") -> 0 | O13: =IFERROR(SUM(H13:K13)/SUM(G13:K13)," ") -> 0.1 | P13: A | Q13: A | R13: A | S13: A | T13: A | U13: A | V13: A | W13: A | X13: A | Y13: A | Z13: A | AA13: A | AB13: A | AC13: A | AD13: SE | AE13: A | AF13: A | AG13: A | AH13: SE | AI13: A | DV13: =CX13+CZ13+DB13+DD13+DF13+DH13+DJ13+DL13+DN13+DP13+DR13+DT13 -> 0 | DW13: =CY13+DA13+DC13+DE13+DG13+DI13+DK13+DM13+DO13+DQ13+DS13+DU13 -> 0 | DY13: 5 SISTEMAS TELEINFORMÁTICOS. 233108. v1
A14: =A13+1 -> 6 | B14: ='BASE DE DATOS'!C15 -> TI | C14: ='BASE DE DATOS'!D15 -> 1028800301 | D14: ='BASE DE DATOS'!B15 -> David Alejandro Betancur Maldonado | E14: EN FORMACIÓN | F14: =IF(I14=0,"",IF(I14>=5,"FALTAS INTERMITENTES",IF(I14>=3,"REVISAR FALTAS",IF(AND(I14<3,I14>0),"CON FALTAS")))) | G14: =COUNTIF(P14:CR14,"A") -> 20 | H14: =COUNTIF(P14:CR14,"CE") -> 0 | I14: =COUNTIF(P14:CR14,"SE") -> 0 | J14: =COUNTIF(P14:CR14,"INC") -> 0 | K14: =COUNTIF(P14:CR14,"LIC") -> 0 | L14: =COUNTIF(P14:CR14,"CLM") -> 0 | M14: =COUNTIF(P14:IA14,"SFF") -> 0 | N14: =COUNTIF(P14:CR14,"RET") -> 0 | O14: =IFERROR(SUM(H14:K14)/SUM(G14:K14)," ") -> 0 | P14: A | Q14: A | R14: A | S14: A | T14: A | U14: A | V14: A | W14: A | X14: A | Y14: A | Z14: A | AA14: A | AB14: A | AC14: A | AD14: A | AE14: A | AF14: A | AG14: A | AH14: A | AI14: A | DV14: =CX14+CZ14+DB14+DD14+DF14+DH14+DJ14+DL14+DN14+DP14+DR14+DT14 -> 0 | DW14: =CY14+DA14+DC14+DE14+DG14+DI14+DK14+DM14+DO14+DQ14+DS14+DU14 -> 0 | DY14: 6 INSTALACION DE REDES DE COMPUTADORES. 233102. v1
A15: =A14+1 -> 7 | B15: ='BASE DE DATOS'!C16 -> TI | C15: ='BASE DE DATOS'!D16 -> 1028620587 | D15: ='BASE DE DATOS'!B16 -> María Camila Buitrago Rengifo | E15: EN FORMACIÓN | F15: =IF(I15=0,"",IF(I15>=5,"FALTAS INTERMITENTES",IF(I15>=3,"REVISAR FALTAS",IF(AND(I15<3,I15>0),"CON FALTAS")))) | G15: =COUNTIF(P15:CR15,"A") -> 20 | H15: =COUNTIF(P15:CR15,"CE") -> 0 | I15: =COUNTIF(P15:CR15,"SE") -> 0 | J15: =COUNTIF(P15:CR15,"INC") -> 0 | K15: =COUNTIF(P15:CR15,"LIC") -> 0 | L15: =COUNTIF(P15:CR15,"CLM") -> 0 | M15: =COUNTIF(P15:IA15,"SFF") -> 0 | N15: =COUNTIF(P15:CR15,"RET") -> 0 | O15: =IFERROR(SUM(H15:K15)/SUM(G15:K15)," ") -> 0 | P15: A | Q15: A | R15: A | S15: A | T15: A | U15: A | V15: A | W15: A | X15: A | Y15: A | Z15: A | AA15: A | AB15: A | AC15: A | AD15: A | AE15: A | AF15: A | AG15: A | AH15: A | AI15: A | DV15: =CX15+CZ15+DB15+DD15+DF15+DH15+DJ15+DL15+DN15+DP15+DR15+DT15 -> 0 | DW15: =CY15+DA15+DC15+DE15+DG15+DI15+DK15+DM15+DO15+DQ15+DS15+DU15 -> 0 | DY15: 7 INTEGRACION DE CONTENIDOS DIGITALES. 524704. v1
A16: =A15+1 -> 8 | B16: ='BASE DE DATOS'!C17 -> TI | C16: ='BASE DE DATOS'!D17 -> 1011205992 | D16: ='BASE DE DATOS'!B17 -> Danna Sofia Calderón Moreno | E16: EN FORMACIÓN | F16: =IF(I16=0,"",IF(I16>=5,"FALTAS INTERMITENTES",IF(I16>=3,"REVISAR FALTAS",IF(AND(I16<3,I16>0),"CON FALTAS")))) -> CON FALTAS | G16: =COUNTIF(P16:CR16,"A") -> 18 | H16: =COUNTIF(P16:CR16,"CE") -> 0 | I16: =COUNTIF(P16:CR16,"SE") -> 2 | J16: =COUNTIF(P16:CR16,"INC") -> 0 | K16: =COUNTIF(P16:CR16,"LIC") -> 0 | L16: =COUNTIF(P16:CR16,"CLM") -> 0 | M16: =COUNTIF(P16:IA16,"SFF") -> 0 | N16: =COUNTIF(P16:CR16,"RET") -> 0 | O16: =IFERROR(SUM(H16:K16)/SUM(G16:K16)," ") -> 0.1 | P16: A | Q16: A | R16: A | S16: A | T16: A | U16: A | V16: A | W16: A | X16: A | Y16: A | Z16: A | AA16: A | AB16: A | AC16: A | AD16: A | AE16: SE | AF16: A | AG16: A | AH16: A | AI16: SE | DV16: =CX16+CZ16+DB16+DD16+DF16+DH16+DJ16+DL16+DN16+DP16+DR16+DT16 -> 0 | DW16: =CY16+DA16+DC16+DE16+DG16+DI16+DK16+DM16+DO16+DQ16+DS16+DU16 -> 0 | DY16: 8 PROGRAMACIÓN DE APLICACIONES PARA DISPOSITIVOS MÓVILES. 228123. v1
A17: =A16+1 -> 9 | B17: ='BASE DE DATOS'!C18 -> TI | C17: ='BASE DE DATOS'!D18 -> 1140923876 | D17: ='BASE DE DATOS'!B18 -> Angie Ximena Camacho Bejarano | E17: EN FORMACIÓN | F17: =IF(I17=0,"",IF(I17>=5,"FALTAS INTERMITENTES",IF(I17>=3,"REVISAR FALTAS",IF(AND(I17<3,I17>0),"CON FALTAS")))) -> CON FALTAS | G17: =COUNTIF(P17:CR17,"A") -> 19 | H17: =COUNTIF(P17:CR17,"CE") -> 0 | I17: =COUNTIF(P17:CR17,"SE") -> 1 | J17: =COUNTIF(P17:CR17,"INC") -> 0 | K17: =COUNTIF(P17:CR17,"LIC") -> 0 | L17: =COUNTIF(P17:CR17,"CLM") -> 0 | M17: =COUNTIF(P17:IA17,"SFF") -> 0 | N17: =COUNTIF(P17:CR17,"RET") -> 0 | O17: =IFERROR(SUM(H17:K17)/SUM(G17:K17)," ") -> 0.05 | P17: A | Q17: A | R17: A | S17: A | T17: A | U17: A | V17: A | W17: A | X17: A | Y17: A | Z17: A | AA17: A | AB17: A | AC17: A | AD17: A | AE17: SE | AF17: A | AG17: A | AH17: A | AI17: A | DV17: =CX17+CZ17+DB17+DD17+DF17+DH17+DJ17+DL17+DN17+DP17+DR17+DT17 -> 0 | DW17: =CY17+DA17+DC17+DE17+DG17+DI17+DK17+DM17+DO17+DQ17+DS17+DU17 -> 0 | DY17: 9 PROGRAMACIÓN DE APLICACIONES Y SERVICIOS PARA LA NUBE. 228122. v1
A18: =A17+1 -> 10 | B18: ='BASE DE DATOS'!C19 -> TI | C18: ='BASE DE DATOS'!D19 -> 1047345388 | D18: ='BASE DE DATOS'!B19 -> Meriet Maryan Cárdenas Escorcia | E18: EN FORMACIÓN | F18: =IF(I18=0,"",IF(I18>=5,"FALTAS INTERMITENTES",IF(I18>=3,"REVISAR FALTAS",IF(AND(I18<3,I18>0),"CON FALTAS")))) | G18: =COUNTIF(P18:CR18,"A") -> 20 | H18: =COUNTIF(P18:CR18,"CE") -> 0 | I18: =COUNTIF(P18:CR18,"SE") -> 0 | J18: =COUNTIF(P18:CR18,"INC") -> 0 | K18: =COUNTIF(P18:CR18,"LIC") -> 0 | L18: =COUNTIF(P18:CR18,"CLM") -> 0 | M18: =COUNTIF(P18:IA18,"SFF") -> 0 | N18: =COUNTIF(P18:CR18,"RET") -> 0 | O18: =IFERROR(SUM(H18:K18)/SUM(G18:K18)," ") -> 0 | P18: A | Q18: A | R18: A | S18: A | T18: A | U18: A | V18: A | W18: A | X18: A | Y18: A | Z18: A | AA18: A | AB18: A | AC18: A | AD18: A | AE18: A | AF18: A | AG18: A | AH18: A | AI18: A | DV18: =CX18+CZ18+DB18+DD18+DF18+DH18+DJ18+DL18+DN18+DP18+DR18+DT18 -> 0 | DW18: =CY18+DA18+DC18+DE18+DG18+DI18+DK18+DM18+DO18+DQ18+DS18+DU18 -> 0 | DY18: 10 PROGRAMACION DE SOFTWARE. 233104. v2
A19: =A18+1 -> 11 | B19: ='BASE DE DATOS'!C20 -> TI | C19: ='BASE DE DATOS'!D20 -> 1013132921 | D19: ='BASE DE DATOS'!B20 -> Sara Nykol Caro Castillo | E19: EN FORMACIÓN | F19: =IF(I19=0,"",IF(I19>=5,"FALTAS INTERMITENTES",IF(I19>=3,"REVISAR FALTAS",IF(AND(I19<3,I19>0),"CON FALTAS")))) | G19: =COUNTIF(P19:CR19,"A") -> 20 | H19: =COUNTIF(P19:CR19,"CE") -> 0 | I19: =COUNTIF(P19:CR19,"SE") -> 0 | J19: =COUNTIF(P19:CR19,"INC") -> 0 | K19: =COUNTIF(P19:CR19,"LIC") -> 0 | L19: =COUNTIF(P19:CR19,"CLM") -> 0 | M19: =COUNTIF(P19:IA19,"SFF") -> 0 | N19: =COUNTIF(P19:CR19,"RET") -> 0 | O19: =IFERROR(SUM(H19:K19)/SUM(G19:K19)," ") -> 0 | P19: A | Q19: A | R19: A | S19: A | T19: A | U19: A | V19: A | W19: A | X19: A | Y19: A | Z19: A | AA19: A | AB19: A | AC19: A | AD19: A | AE19: A | AF19: A | AG19: A | AH19: A | AI19: A | DV19: =CX19+CZ19+DB19+DD19+DF19+DH19+DJ19+DL19+DN19+DP19+DR19+DT19 -> 0 | DW19: =CY19+DA19+DC19+DE19+DG19+DI19+DK19+DM19+DO19+DQ19+DS19+DU19 -> 0 | DY19: 11 SERVICE OPERATION IN BILINGUAL BPO CHANNELS. 137500. v1
A20: =A19+1 -> 12 | B20: ='BASE DE DATOS'!C21 -> TI | C20: ='BASE DE DATOS'!D21 -> 1025148041 | D20: ='BASE DE DATOS'!B21 -> Duver Stiven Castañeda García | E20: EN FORMACIÓN | F20: =IF(I20=0,"",IF(I20>=5,"FALTAS INTERMITENTES",IF(I20>=3,"REVISAR FALTAS",IF(AND(I20<3,I20>0),"CON FALTAS")))) | G20: =COUNTIF(P20:CR20,"A") -> 20 | H20: =COUNTIF(P20:CR20,"CE") -> 0 | I20: =COUNTIF(P20:CR20,"SE") -> 0 | J20: =COUNTIF(P20:CR20,"INC") -> 0 | K20: =COUNTIF(P20:CR20,"LIC") -> 0 | L20: =COUNTIF(P20:CR20,"CLM") -> 0 | M20: =COUNTIF(P20:IA20,"SFF") -> 0 | N20: =COUNTIF(P20:CR20,"RET") -> 0 | O20: =IFERROR(SUM(H20:K20)/SUM(G20:K20)," ") -> 0 | P20: A | Q20: A | R20: A | S20: A | T20: A | U20: A | V20: A | W20: A | X20: A | Y20: A | Z20: A | AA20: A | AB20: A | AC20: A | AD20: A | AE20: A | AF20: A | AG20: A | AH20: A | AI20: A | DV20: =CX20+CZ20+DB20+DD20+DF20+DH20+DJ20+DL20+DN20+DP20+DR20+DT20 -> 0 | DW20: =CY20+DA20+DC20+DE20+DG20+DI20+DK20+DM20+DO20+DQ20+DS20+DU20 -> 0 | DY20: 12 COMUNICACIÓN COMERCIAL Y MARKETING.
A21: =A20+1 -> 13 | B21: ='BASE DE DATOS'!C22 -> TI | C21: ='BASE DE DATOS'!D22 -> 1028869164 | D21: ='BASE DE DATOS'!B22 -> Nicolas Castillo Merchán | E21: EN FORMACIÓN | F21: =IF(I21=0,"",IF(I21>=5,"FALTAS INTERMITENTES",IF(I21>=3,"REVISAR FALTAS",IF(AND(I21<3,I21>0),"CON FALTAS")))) | G21: =COUNTIF(P21:CR21,"A") -> 20 | H21: =COUNTIF(P21:CR21,"CE") -> 0 | I21: =COUNTIF(P21:CR21,"SE") -> 0 | J21: =COUNTIF(P21:CR21,"INC") -> 0 | K21: =COUNTIF(P21:CR21,"LIC") -> 0 | L21: =COUNTIF(P21:CR21,"CLM") -> 0 | M21: =COUNTIF(P21:IA21,"SFF") -> 0 | N21: =COUNTIF(P21:CR21,"RET") -> 0 | O21: =IFERROR(SUM(H21:K21)/SUM(G21:K21)," ") -> 0 | P21: A | Q21: A | R21: A | S21: A | T21: A | U21: A | V21: A | W21: A | X21: A | Y21: A | Z21: A | AA21: A | AB21: A | AC21: A | AD21: A | AE21: A | AF21: A | AG21: A | AH21: A | AI21: A | DV21: =CX21+CZ21+DB21+DD21+DF21+DH21+DJ21+DL21+DN21+DP21+DR21+DT21 -> 0 | DW21: =CY21+DA21+DC21+DE21+DG21+DI21+DK21+DM21+DO21+DQ21+DS21+DU21 -> 0
A22: =A21+1 -> 14 | B22: ='BASE DE DATOS'!C23 -> TI | C22: ='BASE DE DATOS'!D23 -> 1025546752 | D22: ='BASE DE DATOS'!B23 -> Valentina Cespedes Pulido | E22: EN FORMACIÓN | F22: =IF(I22=0,"",IF(I22>=5,"FALTAS INTERMITENTES",IF(I22>=3,"REVISAR FALTAS",IF(AND(I22<3,I22>0),"CON FALTAS")))) | G22: =COUNTIF(P22:CR22,"A") -> 19 | H22: =COUNTIF(P22:CR22,"CE") -> 1 | I22: =COUNTIF(P22:CR22,"SE") -> 0 | J22: =COUNTIF(P22:CR22,"INC") -> 0 | K22: =COUNTIF(P22:CR22,"LIC") -> 0 | L22: =COUNTIF(P22:CR22,"CLM") -> 0 | M22: =COUNTIF(P22:IA22,"SFF") -> 0 | N22: =COUNTIF(P22:CR22,"RET") -> 0 | O22: =IFERROR(SUM(H22:K22)/SUM(G22:K22)," ") -> 0.05 | P22: A | Q22: A | R22: A | S22: A | T22: A | U22: A | V22: A | W22: A | X22: A | Y22: A | Z22: A | AA22: A | AB22: CE | AC22: A | AD22: A | AE22: A | AF22: A | AG22: A | AH22: A | AI22: A | DV22: =CX22+CZ22+DB22+DD22+DF22+DH22+DJ22+DL22+DN22+DP22+DR22+DT22 -> 0 | DW22: =CY22+DA22+DC22+DE22+DG22+DI22+DK22+DM22+DO22+DQ22+DS22+DU22 -> 0
A23: =A22+1 -> 15 | B23: ='BASE DE DATOS'!C24 -> TI | C23: ='BASE DE DATOS'!D24 -> 1033748632 | D23: ='BASE DE DATOS'!B24 -> Dilan Santiago Contreras Gutiérrez | E23: EN FORMACIÓN | F23: =IF(I23=0,"",IF(I23>=5,"FALTAS INTERMITENTES",IF(I23>=3,"REVISAR FALTAS",IF(AND(I23<3,I23>0),"CON FALTAS")))) -> CON FALTAS | G23: =COUNTIF(P23:CR23,"A") -> 19 | H23: =COUNTIF(P23:CR23,"CE") -> 0 | I23: =COUNTIF(P23:CR23,"SE") -> 1 | J23: =COUNTIF(P23:CR23,"INC") -> 0 | K23: =COUNTIF(P23:CR23,"LIC") -> 0 | L23: =COUNTIF(P23:CR23,"CLM") -> 0 | M23: =COUNTIF(P23:IA23,"SFF") -> 0 | N23: =COUNTIF(P23:CR23,"RET") -> 0 | O23: =IFERROR(SUM(H23:K23)/SUM(G23:K23)," ") -> 0.05 | P23: A | Q23: A | R23: A | S23: A | T23: A | U23: A | V23: SE | W23: A | X23: A | Y23: A | Z23: A | AA23: A | AB23: A | AC23: A | AD23: A | AE23: A | AF23: A | AG23: A | AH23: A | AI23: A | DV23: =CX23+CZ23+DB23+DD23+DF23+DH23+DJ23+DL23+DN23+DP23+DR23+DT23 -> 0 | DW23: =CY23+DA23+DC23+DE23+DG23+DI23+DK23+DM23+DO23+DQ23+DS23+DU23 -> 0
A24: =A23+1 -> 16 | B24: ='BASE DE DATOS'!C25 -> TI | C24: ='BASE DE DATOS'!D25 -> 1120738374 | D24: ='BASE DE DATOS'!B25 -> Álvaro Andrés Cuello Hernández | E24: EN FORMACIÓN | F24: =IF(I24=0,"",IF(I24>=5,"FALTAS INTERMITENTES",IF(I24>=3,"REVISAR FALTAS",IF(AND(I24<3,I24>0),"CON FALTAS")))) | G24: =COUNTIF(P24:CR24,"A") -> 20 | H24: =COUNTIF(P24:CR24,"CE") -> 0 | I24: =COUNTIF(P24:CR24,"SE") -> 0 | J24: =COUNTIF(P24:CR24,"INC") -> 0 | K24: =COUNTIF(P24:CR24,"LIC") -> 0 | L24: =COUNTIF(P24:CR24,"CLM") -> 0 | M24: =COUNTIF(P24:IA24,"SFF") -> 0 | N24: =COUNTIF(P24:CR24,"RET") -> 0 | O24: =IFERROR(SUM(H24:K24)/SUM(G24:K24)," ") -> 0 | P24: A | Q24: A | R24: A | S24: A | T24: A | U24: A | V24: A | W24: A | X24: A | Y24: A | Z24: A | AA24: A | AB24: A | AC24: A | AD24: A | AE24: A | AF24: A | AG24: A | AH24: A | AI24: A | DV24: =CX24+CZ24+DB24+DD24+DF24+DH24+DJ24+DL24+DN24+DP24+DR24+DT24 -> 0 | DW24: =CY24+DA24+DC24+DE24+DG24+DI24+DK24+DM24+DO24+DQ24+DS24+DU24 -> 0
A25: =A24+1 -> 17 | B25: ='BASE DE DATOS'!C26 -> TI | C25: ='BASE DE DATOS'!D26 -> 1027530989 | D25: ='BASE DE DATOS'!B26 -> Angie Liseth Gaitán Cárdenas | E25: EN FORMACIÓN | F25: =IF(I25=0,"",IF(I25>=5,"FALTAS INTERMITENTES",IF(I25>=3,"REVISAR FALTAS",IF(AND(I25<3,I25>0),"CON FALTAS")))) | G25: =COUNTIF(P25:CR25,"A") -> 20 | H25: =COUNTIF(P25:CR25,"CE") -> 0 | I25: =COUNTIF(P25:CR25,"SE") -> 0 | J25: =COUNTIF(P25:CR25,"INC") -> 0 | K25: =COUNTIF(P25:CR25,"LIC") -> 0 | L25: =COUNTIF(P25:CR25,"CLM") -> 0 | M25: =COUNTIF(P25:IA25,"SFF") -> 0 | N25: =COUNTIF(P25:CR25,"RET") -> 0 | O25: =IFERROR(SUM(H25:K25)/SUM(G25:K25)," ") -> 0 | P25: A | Q25: A | R25: A | S25: A | T25: A | U25: A | V25: A | W25: A | X25: A | Y25: A | Z25: A | AA25: A | AB25: A | AC25: A | AD25: A | AE25: A | AF25: A | AG25: A | AH25: A | AI25: A | DV25: =CX25+CZ25+DB25+DD25+DF25+DH25+DJ25+DL25+DN25+DP25+DR25+DT25 -> 0 | DW25: =CY25+DA25+DC25+DE25+DG25+DI25+DK25+DM25+DO25+DQ25+DS25+DU25 -> 0
A26: =A25+1 -> 18 | B26: ='BASE DE DATOS'!C27 -> TI | C26: ='BASE DE DATOS'!D27 -> 1027530471 | D26: ='BASE DE DATOS'!B27 -> Yuranny Alexandra García Rincón | E26: EN FORMACIÓN | F26: =IF(I26=0,"",IF(I26>=5,"FALTAS INTERMITENTES",IF(I26>=3,"REVISAR FALTAS",IF(AND(I26<3,I26>0),"CON FALTAS")))) | G26: =COUNTIF(P26:CR26,"A") -> 20 | H26: =COUNTIF(P26:CR26,"CE") -> 0 | I26: =COUNTIF(P26:CR26,"SE") -> 0 | J26: =COUNTIF(P26:CR26,"INC") -> 0 | K26: =COUNTIF(P26:CR26,"LIC") -> 0 | L26: =COUNTIF(P26:CR26,"CLM") -> 0 | M26: =COUNTIF(P26:IA26,"SFF") -> 0 | N26: =COUNTIF(P26:CR26,"RET") -> 0 | O26: =IFERROR(SUM(H26:K26)/SUM(G26:K26)," ") -> 0 | P26: A | Q26: A | R26: A | S26: A | T26: A | U26: A | V26: A | W26: A | X26: A | Y26: A | Z26: A | AA26: A | AB26: A | AC26: A | AD26: A | AE26: A | AF26: A | AG26: A | AH26: A | AI26: A | DV26: =CX26+CZ26+DB26+DD26+DF26+DH26+DJ26+DL26+DN26+DP26+DR26+DT26 -> 0 | DW26: =CY26+DA26+DC26+DE26+DG26+DI26+DK26+DM26+DO26+DQ26+DS26+DU26 -> 0
A27: =A26+1 -> 19 | B27: ='BASE DE DATOS'!C28 -> TI | C27: ='BASE DE DATOS'!D28 -> 1022968721 | D27: ='BASE DE DATOS'!B28 -> Nicoll Mariana García Romero | E27: EN FORMACIÓN | F27: =IF(I27=0,"",IF(I27>=5,"FALTAS INTERMITENTES",IF(I27>=3,"REVISAR FALTAS",IF(AND(I27<3,I27>0),"CON FALTAS")))) -> CON FALTAS | G27: =COUNTIF(P27:CR27,"A") -> 19 | H27: =COUNTIF(P27:CR27,"CE") -> 0 | I27: =COUNTIF(P27:CR27,"SE") -> 1 | J27: =COUNTIF(P27:CR27,"INC") -> 0 | K27: =COUNTIF(P27:CR27,"LIC") -> 0 | L27: =COUNTIF(P27:CR27,"CLM") -> 0 | M27: =COUNTIF(P27:IA27,"SFF") -> 0 | N27: =COUNTIF(P27:CR27,"RET") -> 0 | O27: =IFERROR(SUM(H27:K27)/SUM(G27:K27)," ") -> 0.05 | P27: A | Q27: A | R27: A | S27: A | T27: A | U27: A | V27: A | W27: A | X27: A | Y27: A | Z27: A | AA27: A | AB27: A | AC27: A | AD27: SE | AE27: A | AF27: A | AG27: A | AH27: A | AI27: A | DV27: =CX27+CZ27+DB27+DD27+DF27+DH27+DJ27+DL27+DN27+DP27+DR27+DT27 -> 0 | DW27: =CY27+DA27+DC27+DE27+DG27+DI27+DK27+DM27+DO27+DQ27+DS27+DU27 -> 0
A28: =A27+1 -> 20 | B28: ='BASE DE DATOS'!C29 -> TI | C28: ='BASE DE DATOS'!D29 -> 1027530856 | D28: ='BASE DE DATOS'!B29 -> Laura Camila Gómez Beltrán | E28: EN FORMACIÓN | F28: =IF(I28=0,"",IF(I28>=5,"FALTAS INTERMITENTES",IF(I28>=3,"REVISAR FALTAS",IF(AND(I28<3,I28>0),"CON FALTAS")))) -> CON FALTAS | G28: =COUNTIF(P28:CR28,"A") -> 17 | H28: =COUNTIF(P28:CR28,"CE") -> 2 | I28: =COUNTIF(P28:CR28,"SE") -> 1 | J28: =COUNTIF(P28:CR28,"INC") -> 0 | K28: =COUNTIF(P28:CR28,"LIC") -> 0 | L28: =COUNTIF(P28:CR28,"CLM") -> 0 | M28: =COUNTIF(P28:IA28,"SFF") -> 0 | N28: =COUNTIF(P28:CR28,"RET") -> 0 | O28: =IFERROR(SUM(H28:K28)/SUM(G28:K28)," ") -> 0.15 | P28: A | Q28: A | R28: A | S28: A | T28: A | U28: A | V28: SE | W28: A | X28: A | Y28: A | Z28: CE | AA28: A | AB28: CE | AC28: A | AD28: A | AE28: A | AF28: A | AG28: A | AH28: A | AI28: A | DV28: =CX28+CZ28+DB28+DD28+DF28+DH28+DJ28+DL28+DN28+DP28+DR28+DT28 -> 0 | DW28: =CY28+DA28+DC28+DE28+DG28+DI28+DK28+DM28+DO28+DQ28+DS28+DU28 -> 0
A29: =A28+1 -> 21 | B29: ='BASE DE DATOS'!C30 -> TI | C29: ='BASE DE DATOS'!D30 -> 1019766188 | D29: ='BASE DE DATOS'!B30 -> Mariana Gutiérrez Guzmán | E29: EN FORMACIÓN | F29: =IF(I29=0,"",IF(I29>=5,"FALTAS INTERMITENTES",IF(I29>=3,"REVISAR FALTAS",IF(AND(I29<3,I29>0),"CON FALTAS")))) | G29: =COUNTIF(P29:CR29,"A") -> 20 | H29: =COUNTIF(P29:CR29,"CE") -> 0 | I29: =COUNTIF(P29:CR29,"SE") -> 0 | J29: =COUNTIF(P29:CR29,"INC") -> 0 | K29: =COUNTIF(P29:CR29,"LIC") -> 0 | L29: =COUNTIF(P29:CR29,"CLM") -> 0 | M29: =COUNTIF(P29:IA29,"SFF") -> 0 | N29: =COUNTIF(P29:CR29,"RET") -> 0 | O29: =IFERROR(SUM(H29:K29)/SUM(G29:K29)," ") -> 0 | P29: A | Q29: A | R29: A | S29: A | T29: A | U29: A | V29: A | W29: A | X29: A | Y29: A | Z29: A | AA29: A | AB29: A | AC29: A | AD29: A | AE29: A | AF29: A | AG29: A | AH29: A | AI29: A | DV29: =CX29+CZ29+DB29+DD29+DF29+DH29+DJ29+DL29+DN29+DP29+DR29+DT29 -> 0 | DW29: =CY29+DA29+DC29+DE29+DG29+DI29+DK29+DM29+DO29+DQ29+DS29+DU29 -> 0
A30: =A29+1 -> 22 | B30: ='BASE DE DATOS'!C31 -> TI | C30: ='BASE DE DATOS'!D31 -> 1013637824 | D30: ='BASE DE DATOS'!B31 -> Isabella Hernández Gómez | E30: EN FORMACIÓN | F30: =IF(I30=0,"",IF(I30>=5,"FALTAS INTERMITENTES",IF(I30>=3,"REVISAR FALTAS",IF(AND(I30<3,I30>0),"CON FALTAS")))) | G30: =COUNTIF(P30:CR30,"A") -> 20 | H30: =COUNTIF(P30:CR30,"CE") -> 0 | I30: =COUNTIF(P30:CR30,"SE") -> 0 | J30: =COUNTIF(P30:CR30,"INC") -> 0 | K30: =COUNTIF(P30:CR30,"LIC") -> 0 | L30: =COUNTIF(P30:CR30,"CLM") -> 0 | M30: =COUNTIF(P30:IA30,"SFF") -> 0 | N30: =COUNTIF(P30:CR30,"RET") -> 0 | O30: =IFERROR(SUM(H30:K30)/SUM(G30:K30)," ") -> 0 | P30: A | Q30: A | R30: A | S30: A | T30: A | U30: A | V30: A | W30: A | X30: A | Y30: A | Z30: A | AA30: A | AB30: A | AC30: A | AD30: A | AE30: A | AF30: A | AG30: A | AH30: A | AI30: A | DV30: =CX30+CZ30+DB30+DD30+DF30+DH30+DJ30+DL30+DN30+DP30+DR30+DT30 -> 0 | DW30: =CY30+DA30+DC30+DE30+DG30+DI30+DK30+DM30+DO30+DQ30+DS30+DU30 -> 0
A31: =A30+1 -> 23 | B31: ='BASE DE DATOS'!C32 -> TI | C31: ='BASE DE DATOS'!D32 -> 1018451032 | D31: ='BASE DE DATOS'!B32 -> Valeria Herrera García | E31: EN FORMACIÓN | F31: =IF(I31=0,"",IF(I31>=5,"FALTAS INTERMITENTES",IF(I31>=3,"REVISAR FALTAS",IF(AND(I31<3,I31>0),"CON FALTAS")))) | G31: =COUNTIF(P31:CR31,"A") -> 20 | H31: =COUNTIF(P31:CR31,"CE") -> 0 | I31: =COUNTIF(P31:CR31,"SE") -> 0 | J31: =COUNTIF(P31:CR31,"INC") -> 0 | K31: =COUNTIF(P31:CR31,"LIC") -> 0 | L31: =COUNTIF(P31:CR31,"CLM") -> 0 | M31: =COUNTIF(P31:IA31,"SFF") -> 0 | N31: =COUNTIF(P31:CR31,"RET") -> 0 | O31: =IFERROR(SUM(H31:K31)/SUM(G31:K31)," ") -> 0 | P31: A | Q31: A | R31: A | S31: A | T31: A | U31: A | V31: A | W31: A | X31: A | Y31: A | Z31: A | AA31: A | AB31: A | AC31: A | AD31: A | AE31: A | AF31: A | AG31: A | AH31: A | AI31: A | DV31: =CX31+CZ31+DB31+DD31+DF31+DH31+DJ31+DL31+DN31+DP31+DR31+DT31 -> 0 | DW31: =CY31+DA31+DC31+DE31+DG31+DI31+DK31+DM31+DO31+DQ31+DS31+DU31 -> 0
A32: =A31+1 -> 24 | B32: ='BASE DE DATOS'!C33 -> TI | C32: ='BASE DE DATOS'!D33 -> 1140921303 | D32: ='BASE DE DATOS'!B33 -> Aslhey Yijam Jaramillo Álvarez | E32: EN FORMACIÓN | F32: =IF(I32=0,"",IF(I32>=5,"FALTAS INTERMITENTES",IF(I32>=3,"REVISAR FALTAS",IF(AND(I32<3,I32>0),"CON FALTAS")))) | G32: =COUNTIF(P32:CR32,"A") -> 20 | H32: =COUNTIF(P32:CR32,"CE") -> 0 | I32: =COUNTIF(P32:CR32,"SE") -> 0 | J32: =COUNTIF(P32:CR32,"INC") -> 0 | K32: =COUNTIF(P32:CR32,"LIC") -> 0 | L32: =COUNTIF(P32:CR32,"CLM") -> 0 | M32: =COUNTIF(P32:IA32,"SFF") -> 0 | N32: =COUNTIF(P32:CR32,"RET") -> 0 | O32: =IFERROR(SUM(H32:K32)/SUM(G32:K32)," ") -> 0 | P32: A | Q32: A | R32: A | S32: A | T32: A | U32: A | V32: A | W32: A | X32: A | Y32: A | Z32: A | AA32: A | AB32: A | AC32: A | AD32: A | AE32: A | AF32: A | AG32: A | AH32: A | AI32: A | DV32: =CX32+CZ32+DB32+DD32+DF32+DH32+DJ32+DL32+DN32+DP32+DR32+DT32 -> 0 | DW32: =CY32+DA32+DC32+DE32+DG32+DI32+DK32+DM32+DO32+DQ32+DS32+DU32 -> 0
... A44: =A43+1 -> 36 | B44: ='BASE DE DATOS'!C45 -> TI | C44: ='BASE DE DATOS'!D45 -> 1018447155 | D44: ='BASE DE DATOS'!B45 -> Sara Sofia Romero Trujillo | E44: EN FORMACIÓN | F44: =IF(I44=0,"",IF(I44>=5,"FALTAS INTERMITENTES",IF(I44>=3,"REVISAR FALTAS",IF(AND(I44<3,I44>0),"CON FALTAS")))) | G44: =COUNTIF(P44:CR44,"A") -> 20 | H44: =COUNTIF(P44:CR44,"CE") -> 0 | I44: =COUNTIF(P44:CR44,"SE") -> 0 | J44: =COUNTIF(P44:CR44,"INC") -> 0 | K44: =COUNTIF(P44:CR44,"LIC") -> 0 | L44: =COUNTIF(P44:CR44,"CLM") -> 0 | M44: =COUNTIF(P44:IA44,"SFF") -> 0 | N44: =COUNTIF(P44:CR44,"RET") -> 0 | O44: =IFERROR(SUM(H44:K44)/SUM(G44:K44)," ") -> 0 | P44: A | Q44: A | R44: A | S44: A | T44: A | U44: A | V44: A | W44: A | X44: A | Y44: A | Z44: A | AA44: A | AB44: A | AC44: A | AD44: A | AE44: A | AF44: A | AG44: A | AH44: A | AI44: A | DV44: =CX44+CZ44+DB44+DD44+DF44+DH44+DJ44+DL44+DN44+DP44+DR44+DT44 -> 0 | DW44: =CY44+DA44+DC44+DE44+DG44+DI44+DK44+DM44+DO44+DQ44+DS44+DU44 -> 0
A45: =A44+1 -> 37 | B45: ='BASE DE DATOS'!C46 -> TI | C45: ='BASE DE DATOS'!D46 -> 1140923124 | D45: ='BASE DE DATOS'!B46 -> Erick Santiago Salazar Rojuela | E45: EN FORMACIÓN | G45: =COUNTIF(P45:CR45,"A") -> 19 | H45: =COUNTIF(P45:CR45,"CE") -> 1 | I45: =COUNTIF(P45:CR45,"SE") -> 0 | J45: =COUNTIF(P45:CR45,"INC") -> 0 | K45: =COUNTIF(P45:CR45,"LIC") -> 0 | L45: =COUNTIF(P45:CR45,"CLM") -> 0 | M45: =COUNTIF(P45:IA45,"SFF") -> 0 | N45: =COUNTIF(P45:CR45,"RET") -> 0 | O45: =IFERROR(SUM(H45:K45)/SUM(G45:K45)," ") -> 0.05 | P45: A | Q45: A | R45: A | S45: A | T45: A | U45: A | V45: A | W45: A | X45: A | Y45: A | Z45: A | AA45: A | AB45: CE | AC45: A | AD45: A | AE45: A | AF45: A | AG45: A | AH45: A | AI45: A
A46: =A45+1 -> 38 | B46: ='BASE DE DATOS'!C47 -> TI | C46: ='BASE DE DATOS'!D47 -> 1022980809 | D46: ='BASE DE DATOS'!B47 -> Samuel Alejandro Sanabria Montoya | E46: EN FORMACIÓN | G46: =COUNTIF(P46:CR46,"A") -> 20 | H46: =COUNTIF(P46:CR46,"CE") -> 0 | I46: =COUNTIF(P46:CR46,"SE") -> 0 | J46: =COUNTIF(P46:CR46,"INC") -> 0 | K46: =COUNTIF(P46:CR46,"LIC") -> 0 | L46: =COUNTIF(P46:CR46,"CLM") -> 0 | M46: =COUNTIF(P46:IA46,"SFF") -> 0 | N46: =COUNTIF(P46:CR46,"RET") -> 0 | O46: =IFERROR(SUM(H46:K46)/SUM(G46:K46)," ") -> 0 | P46: A | Q46: A | R46: A | S46: A | T46: A | U46: A | V46: A | W46: A | X46: A | Y46: A | Z46: A | AA46: A | AB46: A | AC46: A | AD46: A | AE46: A | AF46: A | AG46: A | AH46: A | AI46: A
A47: =A46+1 -> 39 | B47: ='BASE DE DATOS'!C48 -> TI | C47: ='BASE DE DATOS'!D48 -> 1016913212 | D47: ='BASE DE DATOS'!B48 -> Samuel Alejandro Tapiero Márquez | E47: EN FORMACIÓN | G47: =COUNTIF(P47:CR47,"A") -> 19 | H47: =COUNTIF(P47:CR47,"CE") -> 1 | I47: =COUNTIF(P47:CR47,"SE") -> 0 | J47: =COUNTIF(P47:CR47,"INC") -> 0 | K47: =COUNTIF(P47:CR47,"LIC") -> 0 | L47: =COUNTIF(P47:CR47,"CLM") -> 0 | M47: =COUNTIF(P47:IA47,"SFF") -> 0 | N47: =COUNTIF(P47:CR47,"RET") -> 0 | O47: =IFERROR(SUM(H47:K47)/SUM(G47:K47)," ") -> 0.05 | P47: A | Q47: A | R47: A | S47: A | T47: A | U47: A | V47: A | W47: A | X47: A | Y47: A | Z47: A | AA47: A | AB47: A | AC47: A | AD47: A | AE47: CE | AF47: A | AG47: A | AH47: A | AI47: A
A48: =A47+1 -> 40 | B48: ='BASE DE DATOS'!C49 -> TI | C48: ='BASE DE DATOS'!D49 -> 1140921453 | D48: ='BASE DE DATOS'!B49 -> Julman Santiago Vargas Castiblanco | E48: EN FORMACIÓN | G48: =COUNTIF(P48:CR48,"A") -> 17 | H48: =COUNTIF(P48:CR48,"CE") -> 0 | I48: =COUNTIF(P48:CR48,"SE") -> 3 | J48: =COUNTIF(P48:CR48,"INC") -> 0 | K48: =COUNTIF(P48:CR48,"LIC") -> 0 | L48: =COUNTIF(P48:CR48,"CLM") -> 0 | M48: =COUNTIF(P48:IA48,"SFF") -> 0 | N48: =COUNTIF(P48:CR48,"RET") -> 0 | O48: =IFERROR(SUM(H48:K48)/SUM(G48:K48)," ") -> 0.15 | P48: A | Q48: A | R48: A | S48: A | T48: A | U48: A | V48: SE | W48: A | X48: A | Y48: A | Z48: A | AA48: A | AB48: A | AC48: A | AD48: A | AE48: A | AF48: SE | AG48: A | AH48: SE | AI48: A
A49: =A48+1 -> 41 | B49: ='BASE DE DATOS'!C50 -> TI | C49: ='BASE DE DATOS'!D50 -> 1033749129 | D49: ='BASE DE DATOS'!B50 -> Michael Estiben Vargas Morales | E49: EN FORMACIÓN | G49: =COUNTIF(P49:CR49,"A") -> 19 | H49: =COUNTIF(P49:CR49,"CE") -> 0 | I49: =COUNTIF(P49:CR49,"SE") -> 1 | J49: =COUNTIF(P49:CR49,"INC") -> 0 | K49: =COUNTIF(P49:CR49,"LIC") -> 0 | L49: =COUNTIF(P49:CR49,"CLM") -> 0 | M49: =COUNTIF(P49:IA49,"SFF") -> 0 | N49: =COUNTIF(P49:CR49,"RET") -> 0 | O49: =IFERROR(SUM(H49:K49)/SUM(G49:K49)," ") -> 0.05 | P49: A | Q49: A | R49: A | S49: A | T49: A | U49: A | V49: A | W49: A | X49: A | Y49: A | Z49: A | AA49: A | AB49: A | AC49: A | AD49: A | AE49: A | AF49: SE | AG49: A | AH49: A | AI49: A
G50: ASIATE | N50: =G8 -> A | P50: =COUNTIF(P9:P49,"A") -> 41 | Q50: =COUNTIF(Q9:Q49,"A") -> 41 | R50: =COUNTIF(R9:R49,"A") -> 41 | S50: =COUNTIF(S9:S49,"A") -> 41 | T50: =COUNTIF(T9:T49,"A") -> 41 | U50: =COUNTIF(U9:U49,"A") -> 41 | V50: =COUNTIF(V9:V49,"A") -> 37 | W50: =COUNTIF(W9:W49,"A") -> 41 | X50: =COUNTIF(X9:X44,"A") -> 36 | Y50: =COUNTIF(Y9:Y44,"A") -> 36 | Z50: =COUNTIF(Z49:Z49,"A") -> 1 | AA50: =COUNTIF(AA9:AA49,"A") -> 39 | AB50: =COUNTIF(AB9:AB49,"A") -> 35 | AC50: =COUNTIF(AC9:AC49,"A") -> 38 | AD50: =COUNTIF(AD9:AD49,"A") -> 36 | AE50: =COUNTIF(AE9:AE49,"A") -> 36 | AF50: =COUNTIF(AF9:AF49,"A") -> 39 | AG50: =COUNTIF(AG9:AG44,"A") -> 36 | AH50: =COUNTIF(AH9:AH49,"A") -> 38 | AI50: =COUNTIF(AI9:AI49,"A") -> 39 | AJ50: =COUNTIF(AJ9:AJ49,"A") -> 0 | AK50: =COUNTIF(AK9:AK49,"A") -> 0 | AL50: =COUNTIF(AL9:AL49,"A") -> 0 | AM50: =COUNTIF(AM9:AM49,"A") -> 0 | AN50: =COUNTIF(AN9:AN49,"A") -> 0 | AO50: =COUNTIF(AO9:AO49,"A") -> 0 | ... CW50: =COUNTIF(CW9:CW49,"A") -> 0 | DV50: =CX50+CZ50+DB50+DD50+DF50+DH50+DJ50+DL50+DN50+DP50+DR50+DT50 -> 0 | DW50: =CY50+DA50+DC50+DE50+DG50+DI50+DK50+DM50+DO50+DQ50+DS50+DU50 -> 0
G51: CON EXCUSA | N51: =H8 -> CE | P51: =COUNTIF(P9:P49,"CE") -> 0 | Q51: =COUNTIF(Q9:Q49,"CE") -> 0 | R51: =COUNTIF(R9:R49,"CE") -> 0 | S51: =COUNTIF(S9:S49,"CE") -> 0 | T51: =COUNTIF(T9:T49,"CE") -> 0 | U51: =COUNTIF(U9:U49,"CE") -> 0 | V51: =COUNTIF(V9:V49,"CE") -> 1 | W51: =COUNTIF(W9:W49,"CE") -> 0 | ... CW51: =COUNTIF(CW9:CW49,"CE") -> 0 | DV51: =CX51+CZ51+DB51+DD51+DF51+DH51+DJ51+DL51+DN51+DP51+DR51+DT51 -> 0 | DW51: =CY51+DA51+DC51+DE51+DG51+DI51+DK51+DM51+DO51+DQ51+DS51+DU51 -> 0
...

Sheet BASE DE DATOS
A1: 0
A3: PROGRAMA DE FORMACIÓN: | C3: 12 COMUNICACIÓN COMERCIAL Y MARKETING.
A4: FICHA O GRUPO: | C4: 3415417 | F4: NÚMERO DE FORMACIÓN POR SEMANA (1 Ó 2): | G4: 2
A5: INSTRUCTOR SENA: | C5: CARLOS ALBERTO SALCEDO DURAN | F5: PRIMER DÍA DE FORMACIÓN (dd/mm/aaaa): | G5: 46083
A6: CORREO INSTRUCTOR: | C6: csalcedo@sena.edu.co | F6: SEGUNDO DÍA DE FORMACIÓN (dd/mm/aaaa): | G6: 46085
A7: INSTITUCIÓN EDUCATIVA: | C7: COLEGIO JUAN LUIS LONDOÑO I.E.D. LA SALLE | F7: GRADO (11): | G7: 10
A8: LINK PORTAFOLIO INSTRUCTOR: | C8: https://sena4-my.sharepoint.com/personal/apuentes_sena_edu_co/_layouts/15/onedrive.aspx?id=%2Fpersonal%2Fapuentes%5Fsena%5Fedu%5Fco%2FDocuments%2FA%C3%91O%202026%2FSUPERVISION%20CUENTAS%20DE%20COBRO%20ARTICULACION%202026%2FCARLOS%20ALBERTO%20SALCEDO%20DURAN%2FPORTAFOLIO%5FDE%5FEVIDENCIAS%5FCARLOS%5FALBERTO%5FSALCEDO%5FDURAN&viewid=f99452b8%2D8171%2D424a%2D90f1%2D23fef74632a4&sharingv2=true&fromShare=true&at=9&CT=1773430642882&OR=OWA%2DNT%2DMail&CID=4411b7ab%2D33a1%2Dbbca%2D929a%2D088530d86f2c&clickParams=eyJYLUFwcE5hbWUiOiJNaWNyb3NvZnQgT3V0bG9vayBXZWIgQXBwIiwiWC1BcHBWZXJzaW9uIjoiMjAyNjAzMDYwMDEuMDQiLCJPUyI6IldpbmRvd3MgMTAifQ%3D%3D&cidOR=Client&FolderCTID=0x012000E2906DDFB502D74489C2F02AFF66F283
A9: No | B9: Nombre | C9: Tipo de documento | D9: No de documento de identidad | E9: Correo electrónico @soy.sena.edu.co | F9: Correo electrónico alterno | G9: Teléfono de contacto | H9: Nombres completos del acudiente | I9: Correo_Acudiente | J9: Teléfono de Acudiente | K9: ID_Drive
A10: 1 | B10: Caren Sofía Acevedo Cortés | C10: TI | D10: 1011210598 | F10: carenacevedo2011@gmail.com | G10: 3222767816 | H10: Yuly Yalile Cortés | I10: yulycortes1989@gmail.com | J10: 3142904958 | K10: https://drive.google.com/drive/folders/1nGZCEiw5Qm49-Xyq-Bib6Px6lhUeOG-G
A11: =A10+1 -> 2 | B11: Helen Natalia Aperador Abaunza | C11: TI | D11: 1021683093 | F11: helennatalia145@gmail.com | G11: 315 2292703 | H11: Sonia Abaunza Camacho | I11: soniaac21@yahoo.es | J11: 319 5917349 | K11: https://drive.google.com/drive/folders/1ZL4PBPXSTiR3u2Bi4V1F9TC2DVIZ5g9o
A12: =A11+1 -> 3 | B12: Paula Valentina Ardila Franco | C12: TI | D12: 1028867289 | F12: ardillapaula92@gmail.com | G12: 3203910222 | H12: Paola Andrea Franco | I12: paoariasfranco@gmail.com | J12: 3212365995 | K12: https://drive.google.com/drive/folders/1ZfIfpXGemPSqeHKLH-Twhzv0_xsk9yQl?usp=drive_link
A13: =A12+1 -> 4 | B13: Janny Sofia Ariza Marín | C13: TI | D13: 1016718433 | F13: jannyariza343@gmail.com | G13: 3106733741 | H13: Luz Adriana Marín Rodríguez | I13: adri-09-27@hotmail.com | J13: 3176890350 | K13: https://drive.google.com/drive/folders/1WYs9r2fnsVXkMYHEFvgUA0NsCdTyt_3l?usp=drive_link
A14: =A13+1 -> 5 | B14: Damián Felipe Benavides Pérez | C14: TI | D14: 1013128025 | F14: damianbenavides684@gmail.com | G14: 3132017680 | H14: Luz Yineth Pérez Pineda | I14: yinethp36@gmail.com | J14: 3125014620 | K14: https://drive.google.com/drive/folders/1V3eUw3GG5qnP59dIpkO0Zpfz4zjRgIF7?usp=drive_link | M14: No tengo acceso
A15: =A14+1 -> 6 | B15: David Alejandro Betancur Maldonado | C15: TI | D15: 1028800301 | F15: dbetancur779@gmail.com | G15: 3025240303 | H15: Denes Maldonado Álvarez | I15: denismaldonado448@gmail.com | J15: 3504932778 | K15: https://drive.google.com/drive/folders/1EJGlXAS0_ANqtQ9NdmXZeUbcAOhrhuHx?usp=drive_link | M15: Link mal creado
A16: =A15+1 -> 7 | B16: María Camila Buitrago Rengifo | C16: TI | D16: 1028620587 | F16: mariacamilabuitragorengifo15@gmail.com | G16: 3053207465 | H16: Paula Andrea | I16: pandrea@homail.es | J16: 3103392133 | K16: https://drive.google.com/drive/folders/1uXVmXhYI4QW9wI74sDIKmCYyUvGmzHxx
A17: =A16+1 -> 8 | B17: Danna Sofia Calderón Moreno | C17: TI | D17: 1011205992 | F17: solecitocalderon2708@gmail.com | G17: 3228937839 | H17: Yenny Carolina Moreno Niño | I17: hasgly1402@hotmail.com | J17: 3212444943 | K17: https://drive.google.com/drive/folders/1AcbqLk7Q2s7D26chVMURfEZ9bejs7qn2?usp=drive_link
A18: =A17+1 -> 9 | B18: Angie Ximena Camacho Bejarano | C18: TI | D18: 1140923876 | F18: angiebejarano0910@gmail.com | G18: 301 9088743 | H18: Amparo Bejarano Londoño | I18: amparobejarano27@gmail.com | J18: 3138278299 | K18: https://drive.google.com/drive/folders/1d9uAbYo-KmqBOVf2F7WUuJDTkSFrFdLP
A19: =A18+1 -> 10 | B19: Meriet Maryan Cárdenas Escorcia | C19: TI | D19: 1047345388 | F19: merietmaryan0515@gmail.com | G19: 302 6972693 | H19: Herlin Escorcia Flórez | I19: yanithescorciaflorez@gmail.com | J19: 3236991408 | K19: https://drive.google.com/drive/folders/1zBhVUGl0XMvFV86KTBazXok380bB50Po
A20: =A19+1 -> 11 | B20: Sara Nykol Caro Castillo | C20: TI | D20: 1013132921 | F20: carocastillosaranykol@gmail.com | G20: 3228955345 | H20: Marisela Castillo | I20: castillomarisela704@gmail.com | J20: 3204764313 | K20: https://drive.google.com/drive/folders/1tJglmPWO29jTIa-ace4BC-1VLxRO5cMn?usp=sharing
A21: =A20+1 -> 12 | B21: Duver Stiven Castañeda García | C21: TI | D21: 1025148041 | F21: duver0224@gmail.com | G21: 3112069421 | H21: Amanda García Niño | I21: amandagarcia2924@gmail.com | J21: 3185432699 | K21: https://drive.google.com/drive/folders/1ZHeNila7MLhDDxzs_YpSyEyTCWirr3jW?usp=sharing
A22: =A21+1 -> 13 | B22: Nicolas Castillo Merchán | C22: TI | D22: 1028869164 | F22: nicolascm1028@gmail.com | G22: 3213262115 | H22: Jennifer Andrea Merchán Cubillos | I22: andrea20_taz@hotmail.com | J22: 3202000148 | K22: https://drive.google.com/drive/folders/1rBWJuMCJzMvuZwiR1UlxKfzg3wWDq95I?usp=drive_link
A23: =A22+1 -> 14 | B23: Valentina Cespedes Pulido | C23: TI | D23: 1025546752 | F23: valcespedes08@gmail.com | G23: 3213987383 | H23: Yuri Pulido | I23: josmirth@hotmail.com | J23: 3214064142 | K23: https://drive.google.com/drive/folders/1gtA8ezWvBpt_NbjPDvqzm_7urnOZ-rUV?usp=drive_link
A24: =A23+1 -> 15 | B24: Dilan Santiago Contreras Gutiérrez | C24: TI | D24: 1033748632 | F24: contreras.gutierrez7dilan@gmail.com | G24: 3108834649 | H24: Ivon Contreras | I24: ivoncontreras857@gmail.com | J24: 3112673683 | K24: https://drive.google.com/drive/folders/1yYHDEElaGWcYT1EPeYbdZ8hgaE3vnREG?usp=drive_link
A25: =A24+1 -> 16 | B25: Álvaro Andrés Cuello Hernández | C25: TI | D25: 1120738374 | F25: alvarocuello575@gmail.com | G25: 3105331732 | H25: Mailen Hernández | I25: mailensofiahernandeznaranjo@gmail.com | J25: 3015851134 | K25: https://drive.google.com/drive/folders/1e5MnNm38wj8rlME9h65wZQxm8wT1fW3i
A26: =A25+1 -> 17 | B26: Angie Liseth Gaitán Cárdenas | C26: TI | D26: 1027530989 | F26: angiegaitan591@gmail.com | G26: 312 3977930 | H26: Cindy Lorena Cárdenas Aldana | I26: angiegaitan591@gmail.com | J26: 3213079806 | K26: https://drive.google.com/drive/folders/1SO8T7_k6tL_jcwaLto6PdAv7PXarxeGR?usp=drive_link
A27: =A26+1 -> 18 | B27: Yuranny Alexandra García Rincón | C27: TI | D27: 1027530471 | F27: yurannygarciar@gmail.com | G27: 3114743873 | H27: Ramiro García García | I27: ramirogarcia1970g@gmail.com | J27: 3208433510 | K27: https://drive.google.com/drive/folders/1V9AuskusGB-IJr0vpwN0a8ZC_U6OXTtU
A28: =A27+1 -> 19 | B28: Nicoll Mariana García Romero | C28: TI | D28: 1022968721 | F28: nmgarcia152009@gmail.com | G28: 3112233931 | H28: Cathalina García Romero | I28: micata89@hotmail.com | J28: 3114878243 | K28: https://drive.google.com/drive/folders/1Dyn45TKWNEOl_Dd2WIYIG56Kk01XNnvZ?usp=drive_link
A29: =A28+1 -> 20 | B29: Laura Camila Gómez Beltrán | C29: TI | D29: 1027530856 | F29: gomezbeltranlauracamila@gmail.com | G29: 3053389920 | H29: Yesenia Milena Beltrán Murcia | I29: yeseniam.beltran@gmail.com | J29: 3177700430 | K29: https://drive.google.com/drive/folders/10W3JOZYnBLERw1Ku3FBXQH17OOqAx6R5
A30: =A29+1 -> 21 | B30: Mariana Gutiérrez Guzmán | C30: TI | D30: 1019766188 | F30: mari.ggutierrez41@gmail.com | G30: 3008784404 | H30: Martha Guzmán | I30: mari.1.99guti@gamil.com | J30: 3046381817 | K30: https://drive.google.com/drive/folders/1RlVaEfQtuWksxUELcNrtbkfnmBB_ewA2?usp=drive_link
A31: =A30+1 -> 22 | B31: Isabella Hernández Gómez | C31: TI | D31: 1013637824 | F31: hernandezgomezisabella8@gmail.com | G31: 3132274010 | H31: Jeison David Hernández Rodríguez | I31: jeisondavidhernanderodriguez@gmail.com | J31: 3006024133 | K31: https://drive.google.com/drive/folders/1f02s4f2abfecWsAVNxq-JKWVTSe_Fcwf?usp=drive_link
A32: =A31+1 -> 23 | B32: Valeria Herrera García | C32: TI | D32: 1018451032 | F32: valeriaherreragarcia51@gmail.com | G32: 3125566819 | H32: Luisa Fernanda | I32: luisafernandavsj@gmail.com | J32: 3135109952 | K32: https://drive.google.com/drive/folders/1MKS2Pjz3SkTdD0D5xspH19NozqSf-lTF?usp=drive_link
A33: =A32+1 -> 24 | B33: Aslhey Yijam Jaramillo Álvarez | C33: TI | D33: 1140921303 | F33: jaramilloasly4@gmail.com | G33: 3157117898 | H33: Katherine Álvarez Ariza | I33: katerinealvarez710@gmail.com | J33: 3106745993 | K33: https://drive.google.com/drive/folders/1FP-_TliOmzZ3MhU8-Bbo_eRDaN83o4TY
A34: =A33+1 -> 25 | B34: Santiago Lizcano Pulido | C34: CC | D34: 1018428656 | F34: santiagolizcanopulido14@gmail.com | G34: 3134172632 | H34: Yuri Pulido | I34: santiagolizcanopulido15@gmail.com | J34: 3214064142 | K34: https://drive.google.com/drive/folders/1nWdpYQ-PSRyTXOePLle3qe1WC9d0boYc?usp=drive_link
A35: =A34+1 -> 26 | B35: Brayan Stiven Martínez Esquivel | C35: TI | D35: 1140923149 | F35: esquibelbrayanextiven@gmail.com | G35: 3104833651 | H35: Yirleni Esquivel Rojas | I35: angelesm1723@hotmail.com | J35: 3013930753 | K35: https://drive.google.com/drive/folders/1lsWmcKXuQ-dCLXiolPQFHfKumHy9g2Ft?usp=drive_link
A36: =A35+1 -> 27 | B36: Lizeth Tatiana Martínez Ramírez | C36: TI | D36: 1027532372 | F36: ramirezlizethtm23@gmail.com | G36: 3245284047 | H36: Bellanira Ramírez | I36: bellaniraramirez34@gmail.com | J36: 3125311107 | K36: https://drive.google.com/drive/folders/1SG_j686OH3igwweU5ry4fLa8v0bNS3_r
A37: =A36+1 -> 28 | B37: Estefanía Martínez Romero | C37: TI | D37: 1056613175 | F37: estefaniamartinezromero22@gmail.com | G37: 3177940362 | H37: Luz Angela Romero Sarmiento | I37: angelaromerosar@hotmail.com | J37: 3132773117 | K37: https://drive.google.com/drive/folders/1jKT7qdz0lTZv-6F9Bb-E_GEVrOP9p-mX
A38: =A37+1 -> 29 | B38: Silvana Montien Beltrán | C38: TI | D38: 1140923878 | F38: silvanamontien@gmail.com | G38: 3223041395 | H38: Martha Elizabeth | I38: melizabethbrojas@gmail.com | J38: 3193169122 | K38: https://drive.google.com/drive/folders/1ASANrByTkWej1THTr6n5IAtJ2hDYw31l
... A40: =A39+1 -> 31 | B40: José Luis Ochoa Bayona | C40: TI | D40: 1012921788 | F40: joseochoa7020@gmail.com | G40: 3134844084 | H40: Emilse Bayona | I40: emilsebayona@gmail,com | J40: 3143239415 | K40: https://drive.google.com/drive/folders/1-_1VRhJ26eR2q2Lo3868pA2FFQHyjP-T?usp=drive_link
A41: =A40+1 -> 32 | B41: Gabriela Quinchía Torres | C41: TI | D41: 1188215179 | F41: jennieisjenniein@gmail.com | G41: 322 4528939 | H41: Irina | I41: irinapatorres@gmail.com | J41: 324 6865193 | K41: https://drive.google.com/drive/folders/1k7CkCQY_SSvrR06nZqJn2xiTkeFA6Hzy?usp=sharing
A42: =A41+1 -> 33 | B42: Tania Valentina Ramos Villada | C42: TI | D42: 1033733815 | F42: valentinavillada815@gmail.com | G42: 3209260931 | H42: Laura Villada | I42: lauravillada815@hotmail.com | J42: 3195162596 | K42: https://drive.google.com/drive/folders/1DzLes7pI88slySjOGkzSu0ekTZXmhGQO
...

Sheet GRUPOS DE PROYECTO
A1: GRUPOS DE TRABAJO
A2: N° 1 | B2: NOMBRE | C2: APELLIDO | D2: CORREO
A3: RITMO CAFÉ | B3: Caren Sofía | C3: Acevedo Cortés | D3: carenacevedo2011@gmail.com
B4: Aslhey Yijam | C4: Jaramillo Álvarez | D4: jaramilloasly4@gmail.com
B5: Samuel Alejandro | C5: Sanabria Montoya | D5: samuelsanabria458@gmail.com
B6: Sara Nykol | C6: Caro Castillo | D6: carocastillosaranykol@gmail.com
A9: N° 2 | B9: NOMBRE | C9: APELLIDO | D9: CORREO
A10: DELI DELI POSTRES | B10: Helen Natalia | C10: Aperador Abaunza | D10: helennatalia145@gmail.com
B11: Estefanía | C11: Martínez Romero | D11: estefaniamartinezromero22@gmail.com
B12: Silvana | C12: Montien Beltrán | D12: silvanamontien@gmail.com
B13: Paula Valentina | C13: Ardila Franco | D13: ardillapaula92@gmail.com
B14: Santiago Lizcano | C14: Pulido | D14: santiagolizcanopulido14@gmail.com
B15: Angie Liseth | C15: Gaitán Cárdenas | D15: angiegaitan591@gmail.com
A17: N° 3 | B17: NOMBRE | C17: APELLIDO | D17: CORREO
A18: DULCE FRAGANCIA | B18: Damián Felipe | C18: Benavides Pérez | D18: damianbenavides684@gmail.com
B19: Julman Santiago | C19: Vargas Castiblanco | D19: santiago0212casti@gmail.com
B20: Isabella | C20: Hernández Gómez | D20: hernandezgomezisabella8@gmail.com
B21: Dilan Santiago | C21: Contreras Gutiérrez | D21: contreras.gutierrez7dilan@gmail.com
B22: Brayan Stiven | C22: Martínez Esquivel | D22: esquibelbrayanextiven@gmail.com
A24: N° 4 | B24: NOMBRE | C24: APELLIDO | D24: CORREO
A25: DISTRIBUIDORA COLIBRI
B26: Danna Sofia | C26: Calderón Moreno | D26: solecitocalderon2708@gmail.com
B27: Nicoll Mariana | C27: García Romero | D27: nmgarcia152009@gmail.com
B28: José Luis | C28: Ochoa Bayona
A31: N° 5 | B31: NOMBRE | C31: APELLIDO | D31: CORREO
A32: BEAUTY LAB | B32: Angie Ximena | C32: Camacho Bejarano | D32: angiebejarano0910@gmail.com
B33: Gabriela | C33: Quinchía Torre | D33: jennieisjenniein@gmail.com
B34: Andrés Felipe | C34: Romero Rojas | D34: andresfeliperomerorojas067@gmail.com
B35: Álvaro Andrés | C35: Cuello Hernández | D35: alvarocuello575@gmail.com
B36: Laura Camila | C36: Gómez Beltrán | D36: gomezbeltranlauracamila@gmail.com
B37: Mariana | C37: Gutiérrez Guzmán | D37: mari.ggutierrez41@gmail.com
A39: N° 6 | B39: NOMBRE | C39: APELLIDO | D39: CORREO
A40: KUMENZA | B40: María Camila | C40: Buitrago Rengifo | D40: mariacamilabuitragorengifo15@gmail.com
B41: Valentina | C41: Cespedes Pulido | D41: valcespedes08@gmail.com
B42: Meriet Maryan | C42: Cárdenas Escorcia | D42: merietmaryan0515@gmail.com
B43: Lizeth Tatiana | C43: Martínez Ramírez | D43: ramirezlizethtm23@gmail.com
B44: Andrés | C44: Rodríguez Salinas | D44: rodriguezsalinasandres10@gmail.com
B45: Erick Santiago | C45: Salazar Rojuela | D45: salazarorjuelaericksantiago@gmail.com
A47: N° 7 | B47: NOMBRE | C47: APELLIDO | D47: CORREO
A48: JEANSCOLOM | B48: Duver Stiven | C48: Castañeda García | D48: duver0224@gmail.com
...
